(.venv) PS C:\Dev\SiteReportAutomate> python download_report.py
Traceback (most recent call last):
  File "C:\Dev\SiteReportAutomate\download_report.py", line 48, in <module>
    asyncio.run(main())
    ~~~~~~~~~~~^^^^^^^^
  File "C:\Users\au016207\AppData\Local\Programs\Python\Python313\Lib\asyncio\runners.py", line 195, in run
    return runner.run(main)
           ~~~~~~~~~~^^^^^^
  File "C:\Users\au016207\AppData\Local\Programs\Python\Python313\Lib\asyncio\runners.py", line 118, in run
    return self._loop.run_until_complete(task)
           ~~~~~~~~~~~~~~~~~~~~~~~~~~~~~^^^^^^
  File "C:\Users\au016207\AppData\Local\Programs\Python\Python313\Lib\asyncio\base_events.py", line 725, in run_until_complete
    return future.result()
           ~~~~~~~~~~~~~^^
  File "C:\Dev\SiteReportAutomate\download_report.py", line 23, in main
    await page.goto(REPORT_URL, wait_until="networkidle")
  File "C:\Dev\SiteReportAutomate\.venv\Lib\site-packages\playwright\async_api\_generated.py", line 8992, in goto
    await self._impl_obj.goto(
        url=url, timeout=timeout, waitUntil=wait_until, referer=referer
    )
  File "C:\Dev\SiteReportAutomate\.venv\Lib\site-packages\playwright\_impl\_page.py", line 556, in goto
    return await self._main_frame.goto(**locals_to_params(locals()))
           ^^^^^^^^^^^^^^^^^^^^^^^^^^^^^^^^^^^^^^^^^^^^^^^^^^^^^^^^^
  File "C:\Dev\SiteReportAutomate\.venv\Lib\site-packages\playwright\_impl\_frame.py", line 153, in goto
    await self._channel.send(
        "goto", self._navigation_timeout, locals_to_params(locals())
    )
  File "C:\Dev\SiteReportAutomate\.venv\Lib\site-packages\playwright\_impl\_connection.py", line 69, in send
    return await self._connection.wrap_api_call(
           ^^^^^^^^^^^^^^^^^^^^^^^^^^^^^^^^^^^^^
    ...<3 lines>...
    )
    ^
  File "C:\Dev\SiteReportAutomate\.venv\Lib\site-packages\playwright\_impl\_connection.py", line 558, in wrap_api_call
    raise rewrite_error(error, f"{parsed_st['apiName']}: {error}") from None
playwright._impl._errors.Error: Page.goto: net::ERR_INVALID_AUTH_CREDENTIALS at https://sgpaphq-epbbcs3.dc01.fujixerox.net/firmware/DeviceList.aspx
Call log:
  - navigating to "https://sgpaphq-epbbcs3.dc01.fujixerox.net/firmware/DeviceList.aspx", waiting until "networkidle"